Workbook

Sheet Dashboard
B2: This Week FII Net (Cr) | D2: This Week DII Net (Cr) | F2: Current Signal | H2: Sector Concentration | J2: FII-Nifty Correlation
B3: =SUMIFS(FII_DII_raw_synthetic_Jan_Jun2026[Net_Flow_Cr],FII_DII_raw_synthetic_Jan_Jun2026[Week_Num],MAX(FII_DII_raw_synthetic_Jan_Jun2026[Week_Num]),FII_DII_raw_synthetic_Jan_Jun2026[Entity_Type],"FII") -> 3652.78 | D3: =SUMIFS(FII_DII_raw_synthetic_Jan_Jun2026[Net_Flow_Cr],FII_DII_raw_synthetic_Jan_Jun2026[Week_Num],MAX(FII_DII_raw_synthetic_Jan_Jun2026[Week_Num]),FII_DII_raw_synthetic_Jan_Jun2026[Entity_Type],"DII") -> 652.85 | F3: =INDEX(Flow_Model!W:W,MATCH(MAX(Flow_Model!A:A),Flow_Model!A:A,0)) -> Divergent Flow | H3: =INDEX(Flow_Model!S:S,MATCH(MAX(Flow_Model!A:A),Flow_Model!A:A,0)) -> 0.65952901 | J3: =Flow_Model!V2 -> -0.017208541
B6: Date | C6: FII_Net | D6: DII_Net | E6: Nifty_Close
B7: =Flow_Model!A2 -> 46023 | C7: =Flow_Model!B2 -> -2180.65 | D7: =Flow_Model!C2 -> 845.45 | E7: =IFERROR(_xlfn.XLOOKUP(B7,'Nifty 50 Historical Data'!A:A,'Nifty 50 Historical Data'!B:B),"") -> 26146.55
B8: =Flow_Model!A3 -> 46024 | C8: =Flow_Model!B3 -> -1365.57 | D8: =Flow_Model!C3 -> -108.08 | E8: =IFERROR(_xlfn.XLOOKUP(B8,'Nifty 50 Historical Data'!A:A,'Nifty 50 Historical Data'!B:B),"") -> 26328.55
B9: =Flow_Model!A4 -> 46026 | C9: =Flow_Model!B4 -> 1818.05 | D9: =Flow_Model!C4 -> 38.73 | E9: =IFERROR(_xlfn.XLOOKUP(B9,'Nifty 50 Historical Data'!A:A,'Nifty 50 Historical Data'!B:B),"")
B10: =Flow_Model!A5 -> 46027 | C10: =Flow_Model!B5 -> -733.3 | D10: =Flow_Model!C5 -> 779.7 | E10: =IFERROR(_xlfn.XLOOKUP(B10,'Nifty 50 Historical Data'!A:A,'Nifty 50 Historical Data'!B:B),"") -> 26250.3
B11: =Flow_Model!A6 -> 46028 | C11: =Flow_Model!B6 -> -3622.57 | D11: =Flow_Model!C6 -> 3347.9 | E11: =IFERROR(_xlfn.XLOOKUP(B11,'Nifty 50 Historical Data'!A:A,'Nifty 50 Historical Data'!B:B),"") -> 26178.7
B12: =Flow_Model!A7 -> 46029 | C12: =Flow_Model!B7 -> -1768.06 | D12: =Flow_Model!C7 -> -372.19 | E12: =IFERROR(_xlfn.XLOOKUP(B12,'Nifty 50 Historical Data'!A:A,'Nifty 50 Historical Data'!B:B),"") -> 26140.75
B13: =Flow_Model!A8 -> 46030 | C13: =Flow_Model!B8 -> 688.41 | D13: =Flow_Model!C8 -> -1471.16 | E13: =IFERROR(_xlfn.XLOOKUP(B13,'Nifty 50 Historical Data'!A:A,'Nifty 50 Historical Data'!B:B),"") -> 25876.85
B14: =Flow_Model!A9 -> 46031 | C14: =Flow_Model!B9 -> -1508.47 | D14: =Flow_Model!C9 -> -452.34 | E14: =IFERROR(_xlfn.XLOOKUP(B14,'Nifty 50 Historical Data'!A:A,'Nifty 50 Historical Data'!B:B),"") -> 25683.3
B15: =Flow_Model!A10 -> 46034 | C15: =Flow_Model!B10 -> -1801.5 | D15: =Flow_Model!C10 -> 929.86 | E15: =IFERROR(_xlfn.XLOOKUP(B15,'Nifty 50 Historical Data'!A:A,'Nifty 50 Historical Data'!B:B),"") -> 25790.25
B16: =Flow_Model!A11 -> 46035 | C16: =Flow_Model!B11 -> 1150.59 | D16: =Flow_Model!C11 -> -2409.58 | E16: =IFERROR(_xlfn.XLOOKUP(B16,'Nifty 50 Historical Data'!A:A,'Nifty 50 Historical Data'!B:B),"") -> 25732.3
B17: =Flow_Model!A12 -> 46036 | C17: =Flow_Model!B12 -> 435.57 | D17: =Flow_Model!C12 -> -3322.44 | E17: =IFERROR(_xlfn.XLOOKUP(B17,'Nifty 50 Historical Data'!A:A,'Nifty 50 Historical Data'!B:B),"") -> 25665.6
B18: =Flow_Model!A13 -> 46037 | C18: =Flow_Model!B13 -> -2230.2 | D18: =Flow_Model!C13 -> -1759.25 | E18: =IFERROR(_xlfn.XLOOKUP(B18,'Nifty 50 Historical Data'!A:A,'Nifty 50 Historical Data'!B:B),"")
... B134: =Flow_Model!A129 -> 46203 | C134: =Flow_Model!B129 -> 1541.5 | D134: =Flow_Model!C129 -> -1951.71 | E134: =IFERROR(_xlfn.XLOOKUP(B134,'Nifty 50 Historical Data'!A:A,'Nifty 50 Historical Data'!B:B),"")
B140: Market Signal Status
B141: FII Activity | C141: =INDEX(Flow_Model!W:W,MATCH(MAX(Flow_Model!A:A),Flow_Model!A:A,0)) -> Divergent Flow
B142: Concentration Risk | C142: =IF(INDEX(Flow_Model!S:S,MATCH(MAX(Flow_Model!A:A),Flow_Model!A:A,0))>0.75,"High",IF(INDEX(Flow_Model!S:S,MATCH(MAX(Flow_Model!A:A),Flow_Model!A:A,0))>0.5,"Moderate","Low")) -> Moderate
B145: AI-Generated Summary
B146: ="As of "&TEXT(INDEX(Flow_Model!A:A,MATCH(MAX(Flow_Model!A:A),Flow_Model!A:A,0)),"DD-MMM-YYYY")&", FII activity shows "&INDEX(Flow_Model!W:W,MATCH(MAX(Flow_Model!A:A),Flow_Model!A:A,0))&" with a Sector Concentration of "&TEXT(INDEX(Flow_Model!S:S,MATCH(MAX(Flow_Model!A:A),Flow_Model!A:A,0)),"0%")&", while DII flows remain "&IF(INDEX(Flow_Model!C:C,MATCH(MAX(Flow_Model!A:A),Flow_Model!A:A,0))>=0,"net positive","net negative")&" at ₹"&TEXT(ABS(INDEX(Flow_Model!C:C,MATCH(MAX(Flow_Model!A:A),Flow_Model!A:A,0))),"#,##0")&" Cr. "&IF(INDEX(Flow_Model!T:T,MATCH(MAX(Flow_Model!A:A),Flow_Model!A:A,0))="","NIFTY 50 move unavailable for that day","NIFTY 50 moved "&TEXT(INDEX(Flow_Model!T:T,MATCH(MAX(Flow_Model!A:A),Flow_Model!A:A,0)),"0.00")&"% that day")&", with a "&IF(ABS(INDEX(Flow_Model!V:V,MATCH(MAX(Flow_Model!A:A),Flow_Model!A:A,0)))<0.1,"weak",IF(ABS(INDEX(Flow_Model!V:V,MATCH(MAX(Flow_Model!A:A),Flow_Model!A:A,0)))<0.4,"moderate","strong"))&" flow-market correlation of "&TEXT(INDEX(Flow_Model!V:V,MATCH(MAX(Flow_Model!A:A),Flow_Model!A:A,0)),"0.00")&"." -> As of 30-Jun-2026, FII activity shows Divergent Flow with a Sector Concentration of 66%, while DII flows remain net negative at ₹1,952 Cr. NIFTY 50 move unavailable for that day, with a weak flow-market correlation of 0.00.

Sheet FII_DII_raw_synthetic_Jan-Jun20
A1: Date | B1: Entity_Type | C1: Sector | D1: Gross_Buy_Cr | E1: Gross_Sell_Cr | F1: Net_Flow_Cr | G1: Remarks | H1: Week_Num
A2: 46122 | B2: FII | C2: Pharmaceuticals | D2: 531.4 | E2: 1211.38 | F2: -679.98 | H2: =WEEKNUM(A2,2) -> 15
A3: 46023 | B3: FII | C3: Pharmaceuticals | D3: 328.22 | E3: 1014.94 | F3: -686.72 | H3: =WEEKNUM(A3,2) -> 1
A4: 46099 | B4: DII | C4: Pharmaceuticals | D4: 476.42 | E4: 250.06 | F4: 226.36 | H4: =WEEKNUM(A4,2) -> 12
A5: 46167 | B5: DII | C5: Pharmaceuticals | D5: 850.63 | E5: 2417.98 | F5: -1567.35 | H5: =WEEKNUM(A5,2) -> 22
A6: 46052 | B6: DII | C6: Pharmaceuticals | D6: 2313.58 | E6: 1581.66 | F6: 731.92 | H6: =WEEKNUM(A6,2) -> 5
A7: 46062 | B7: DII | C7: Energy | D7: 1528.34 | E7: 1025.02 | F7: 503.32 | H7: =WEEKNUM(A7,2) -> 7
A8: 46104 | B8: DII | C8: Energy | D8: 2350.1 | E8: 1279.36 | F8: 1070.74 | H8: =WEEKNUM(A8,2) -> 13
A9: 46044 | B9: DII | C9: Information Technology | D9: 837.12 | E9: 460.17 | F9: 376.95 | H9: =WEEKNUM(A9,2) -> 4
A10: 46052 | B10: FII | C10: Realty | D10: 707.02 | E10: 805.4 | F10: -98.38 | H10: =WEEKNUM(A10,2) -> 5
A11: 46077 | B11: FII | C11: Realty | D11: 1896.12 | E11: 1897.3 | F11: -1.18 | H11: =WEEKNUM(A11,2) -> 9
A12: 46056 | B12: DII | C12: Realty | D12: 2551.86 | E12: 2521.45 | F12: 30.41 | H12: =WEEKNUM(A12,2) -> 6
A13: 46079 | B13: FII | C13: Realty | D13: 2087.73 | E13: 2174.69 | F13: -86.96 | H13: =WEEKNUM(A13,2) -> 9
... A36: 46028 | B36: FII | C36: Realty | D36: 961.17 | E36: 1875.31 | F36: -914.14 | H36: =WEEKNUM(A36,2) -> 2
A37: 46161 | B37: FII | C37: Metals | D37: 1105.31 | E37: 1795.77 | F37: -690.46 | G37: Reported in Lakh | H37: =WEEKNUM(A37,2) -> 21
A38: 46184 | B38: DII | C38: Information Technology | D38: 2073.78 | E38: 1557.56 | F38: 516.22 | H38: =WEEKNUM(A38,2) -> 24
A39: 46161 | B39: FII | C39: FMCG | D39: 1630.95 | E39: 1711.34 | F39: -80.39 | H39: =WEEKNUM(A39,2) -> 21
A40: 46097 | B40: DII | C40: Metals | D40: 1630.94 | E40: 2320.02 | F40: -689.08 | H40: =WEEKNUM(A40,2) -> 12
A41: 46063 | B41: FII | C41: Banking | D41: 529.56 | E41: 593.59 | F41: -64.03 | H41: =WEEKNUM(A41,2) -> 7
A42: 46185 | B42: FII | C42: FMCG | D42: 1708.01 | E42: 1054.8 | F42: 653.21 | H42: =WEEKNUM(A42,2) -> 24
A43: 46057 | B43: FII | C43: Infrastructure | D43: 1029.94 | E43: 1410.36 | F43: -380.42 | H43: =WEEKNUM(A43,2) -> 6
A44: 46202 | B44: FII | C44: Information Technology | D44: 2103.68 | E44: 1222.16 | F44: 881.52 | H44: =WEEKNUM(A44,2) -> 27
A45: 46105 | B45: DII | C45: Infrastructure | D45: 1753.53 | E45: 358.19 | F45: 1395.34 | H45: =WEEKNUM(A45,2) -> 13
A46: 46055 | B46: DII | C46: Energy | D46: 1006.71 | E46: 1829.94 | F46: -823.23 | H46: =WEEKNUM(A46,2) -> 6
A47: 46143 | B47: DII | C47: Banking | D47: 2043.95 | E47: 334.25 | F47: 1709.7 | H47: =WEEKNUM(A47,2) -> 18
A48: 46071 | B48: DII | C48: Pharmaceuticals | D48: 688.54 | E48: 1518.13 | F48: -829.59 | H48: =WEEKNUM(A48,2) -> 8
A49: 46064 | B49: DII | C49: Energy | D49: 1550.82 | E49: 929.21 | F49: 621.61 | H49: =WEEKNUM(A49,2) -> 7
... A54: 46049 | B54: FII | C54: FMCG | D54: 1338.97 | E54: 1492.15 | F54: -153.18 | H54: =WEEKNUM(A54,2) -> 5
A55: 46175 | B55: DII | C55: Metals | D55: 820.05 | E55: 871.18 | F55: -51.13 | G55: Reported in Lakh | H55: =WEEKNUM(A55,2) -> 23
A56: 46028 | B56: FII | C56: Infrastructure | D56: 928.77 | E56: 1917.51 | F56: -988.74 | H56: =WEEKNUM(A56,2) -> 2
A57: 46125 | B57: DII | C57: Banking | D57: 263.08 | E57: 1529.65 | F57: -1266.57 | H57: =WEEKNUM(A57,2) -> 16
A58: 46125 | B58: DII | C58: Energy | D58: 1523.95 | E58: 1668.68 | F58: -144.73 | H58: =WEEKNUM(A58,2) -> 16
A59: 46195 | B59: DII | C59: Realty | D59: 952.04 | E59: 2314.37 | F59: -1362.33 | H59: =WEEKNUM(A59,2) -> 26
A60: 46101 | B60: DII | C60: Energy | D60: 1619.41 | E60: 1044.66 | F60: 574.75 | H60: =WEEKNUM(A60,2) -> 12
A61: 46162 | B61: DII | C61: Infrastructure | D61: 1740.34 | E61: 340.96 | F61: 1399.38 | H61: =WEEKNUM(A61,2) -> 21
A62: 46188 | B62: FII | C62: Metals | D62: 573.57 | E62: 574.23 | F62: -0.66 | H62: =WEEKNUM(A62,2) -> 25
A63: 46144 | B63: DII | C63: Energy | D63: 2339.78 | E63: 1303.37 | F63: 1036.41 | H63: =WEEKNUM(A63,2) -> 18
A64: 46045 | B64: DII | C64: Telecom | D64: 1180.14 | E64: 1165.76 | F64: 14.38 | H64: =WEEKNUM(A64,2) -> 4
A65: 46135 | B65: DII | C65: Metals | D65: 2222.24 | E65: 1624.94 | F65: 597.3 | G65: Reported in Lakh | H65: =WEEKNUM(A65,2) -> 17
A66: 46077 | B66: DII | C66: Information Technology | D66: 1992.24 | E66: 1241.53 | F66: 750.71 | H66: =WEEKNUM(A66,2) -> 9
...

Sheet Flow_Model
A1: Date | B1: FII_Net_Cr | C1: DII_Net_Cr. | D1: FII_5Day_Avg | E1: DII_5Day_Avg | F1: Divergence_Index | G1: Pharmaceuticals | H1: Energy | I1: Information Technology | J1: Realty | K1: Metals | L1: FMCG | M1: Banking | N1: Telecom | O1: Infrastructure | P1: Automobile | Q1: Total_FII_Abs | R1: Top2_Abs_Sum | S1: Sector_Concentration_Ratio | T1: Nifty_Change_Pct | V1: FII_Nifty_Correlation | W1: Signal_Flag | X1: FII_Threshold | Y1: Week_Num | Z1: Scenario | AA1: FII_Multiplier | AB1: DII_Multiplier | AD1: Selected_Scenario | AE1: Active_FII_Mult | AF1: Active_DII_Mult | AH1: Forecast_Date | AI1: Forecast_FII | AJ1: Forecast_DII
A2: {=_xlfn._xlws.SORT(_xlfn.UNIQUE(FII_DII_raw_synthetic_Jan_Jun2026[Date]))} -> 46023 | B2: =SUMIFS(FII_DII_raw_synthetic_Jan_Jun2026[Net_Flow_Cr], FII_DII_raw_synthetic_Jan_Jun2026[Date], A2, FII_DII_raw_synthetic_Jan_Jun2026[Entity_Type], "FII") -> -2180.65 | C2: =SUMIFS(FII_DII_raw_synthetic_Jan_Jun2026[Net_Flow_Cr], FII_DII_raw_synthetic_Jan_Jun2026[Date], A2, FII_DII_raw_synthetic_Jan_Jun2026[Entity_Type], "DII") -> 845.45 | F2: =ABS(B2)-ABS(C2) -> 1335.2 | G2: =SUMIFS(FII_DII_raw_synthetic_Jan_Jun2026[Net_Flow_Cr], FII_DII_raw_synthetic_Jan_Jun2026[Date], $A2, FII_DII_raw_synthetic_Jan_Jun2026[Entity_Type], "FII", FII_DII_raw_synthetic_Jan_Jun2026[Sector], G$1) -> -686.72 | H2: =SUMIFS(FII_DII_raw_synthetic_Jan_Jun2026[Net_Flow_Cr], FII_DII_raw_synthetic_Jan_Jun2026[Date], $A2, FII_DII_raw_synthetic_Jan_Jun2026[Entity_Type], "FII", FII_DII_raw_synthetic_Jan_Jun2026[Sector], H$1) -> 0 | I2: =SUMIFS(FII_DII_raw_synthetic_Jan_Jun2026[Net_Flow_Cr], FII_DII_raw_synthetic_Jan_Jun2026[Date], $A2, FII_DII_raw_synthetic_Jan_Jun2026[Entity_Type], "FII", FII_DII_raw_synthetic_Jan_Jun2026[Sector], I$1) -> -1052.19 | J2: =SUMIFS(FII_DII_raw_synthetic_Jan_Jun2026[Net_Flow_Cr], FII_DII_raw_synthetic_Jan_Jun2026[Date], $A2, FII_DII_raw_synthetic_Jan_Jun2026[Entity_Type], "FII", FII_DII_raw_synthetic_Jan_Jun2026[Sector], J$1) -> 0 | K2: =SUMIFS(FII_DII_raw_synthetic_Jan_Jun2026[Net_Flow_Cr], FII_DII_raw_synthetic_Jan_Jun2026[Date], $A2, FII_DII_raw_synthetic_Jan_Jun2026[Entity_Type], "FII", FII_DII_raw_synthetic_Jan_Jun2026[Sector], K$1) -> 0 | L2: =SUMIFS(FII_DII_raw_synthetic_Jan_Jun2026[Net_Flow_Cr], FII_DII_raw_synthetic_Jan_Jun2026[Date], $A2, FII_DII_raw_synthetic_Jan_Jun2026[Entity_Type], "FII", FII_DII_raw_synthetic_Jan_Jun2026[Sector], L$1) -> -441.74 | M2: =SUMIFS(FII_DII_raw_synthetic_Jan_Jun2026[Net_Flow_Cr], FII_DII_raw_synthetic_Jan_Jun2026[Date], $A2, FII_DII_raw_synthetic_Jan_Jun2026[Entity_Type], "FII", FII_DII_raw_synthetic_Jan_Jun2026[Sector], M$1) -> 0 | N2: =SUMIFS(FII_DII_raw_synthetic_Jan_Jun2026[Net_Flow_Cr], FII_DII_raw_synthetic_Jan_Jun2026[Date], $A2, FII_DII_raw_synthetic_Jan_Jun2026[Entity_Type], "FII", FII_DII_raw_synthetic_Jan_Jun2026[Sector], N$1) -> 0 | ... P2: =SUMIFS(FII_DII_raw_synthetic_Jan_Jun2026[Net_Flow_Cr], FII_DII_raw_synthetic_Jan_Jun2026[Date], $A2, FII_DII_raw_synthetic_Jan_Jun2026[Entity_Type], "FII", FII_DII_raw_synthetic_Jan_Jun2026[Sector], P$1) -> 0 | Q2: {=SUMPRODUCT(ABS(G2:P2))} -> 2180.65 | R2: {=LARGE(ABS(G2:P2),1)+LARGE(ABS(G2:P2),2)} -> 1738.91 | S2: =IFERROR(R2/Q2,0) -> 0.79742737 | T2: =IFERROR(_xlfn.XLOOKUP(A2, 'Nifty 50 Historical Data'!A:A, 'Nifty 50 Historical Data'!G:G), "") -> 0.06 | V2: =CORREL(B2:B129, T2:T129) -> -0.017208541 | W2: =IF(B2<=-$X$2,"Strong FII Selling",IF(B2>=$X$2,"Strong FII Buying",IF(OR(B2=0,C2=0),"Neutral",IF(SIGN(B2)<>SIGN(C2),"Divergent Flow","Aligned Flow")))) -> Strong FII Selling | X2: {=AVERAGE(ABS(B2:B129))*1.5} -> 1928.5651 | Y2: =WEEKNUM(A2,2) -> 1 | Z2: Bull | AA2: 1.5 | AB2: 1.2 | AD2: Base | AE2: =_xlfn.XLOOKUP(AD2,Z2:Z4,AA2:AA4) -> 1 | AF2: =_xlfn.XLOOKUP(AD2,Z2:Z4,AB2:AB4) -> 1 | AH2: =MAX(A2:A129)+1 -> 46204 | AI2: =$D$129*$AE$2 -> 804.82 | AJ2: =$E$129*$AF$2 -> -396.664
A3: 46024 | B3: =SUMIFS(FII_DII_raw_synthetic_Jan_Jun2026[Net_Flow_Cr], FII_DII_raw_synthetic_Jan_Jun2026[Date], A3, FII_DII_raw_synthetic_Jan_Jun2026[Entity_Type], "FII") -> -1365.57 | C3: =SUMIFS(FII_DII_raw_synthetic_Jan_Jun2026[Net_Flow_Cr], FII_DII_raw_synthetic_Jan_Jun2026[Date], A3, FII_DII_raw_synthetic_Jan_Jun2026[Entity_Type], "DII") -> -108.08 | F3: =ABS(B3)-ABS(C3) -> 1257.49 | G3: =SUMIFS(FII_DII_raw_synthetic_Jan_Jun2026[Net_Flow_Cr], FII_DII_raw_synthetic_Jan_Jun2026[Date], $A3, FII_DII_raw_synthetic_Jan_Jun2026[Entity_Type], "FII", FII_DII_raw_synthetic_Jan_Jun2026[Sector], G$1) -> 0 | H3: =SUMIFS(FII_DII_raw_synthetic_Jan_Jun2026[Net_Flow_Cr], FII_DII_raw_synthetic_Jan_Jun2026[Date], $A3, FII_DII_raw_synthetic_Jan_Jun2026[Entity_Type], "FII", FII_DII_raw_synthetic_Jan_Jun2026[Sector], H$1) -> 0 | I3: =SUMIFS(FII_DII_raw_synthetic_Jan_Jun2026[Net_Flow_Cr], FII_DII_raw_synthetic_Jan_Jun2026[Date], $A3, FII_DII_raw_synthetic_Jan_Jun2026[Entity_Type], "FII", FII_DII_raw_synthetic_Jan_Jun2026[Sector], I$1) -> -1123.77 | J3: =SUMIFS(FII_DII_raw_synthetic_Jan_Jun2026[Net_Flow_Cr], FII_DII_raw_synthetic_Jan_Jun2026[Date], $A3, FII_DII_raw_synthetic_Jan_Jun2026[Entity_Type], "FII", FII_DII_raw_synthetic_Jan_Jun2026[Sector], J$1) -> 0 | K3: =SUMIFS(FII_DII_raw_synthetic_Jan_Jun2026[Net_Flow_Cr], FII_DII_raw_synthetic_Jan_Jun2026[Date], $A3, FII_DII_raw_synthetic_Jan_Jun2026[Entity_Type], "FII", FII_DII_raw_synthetic_Jan_Jun2026[Sector], K$1) -> 30.8 | L3: =SUMIFS(FII_DII_raw_synthetic_Jan_Jun2026[Net_Flow_Cr], FII_DII_raw_synthetic_Jan_Jun2026[Date], $A3, FII_DII_raw_synthetic_Jan_Jun2026[Entity_Type], "FII", FII_DII_raw_synthetic_Jan_Jun2026[Sector], L$1) -> 296.72 | M3: =SUMIFS(FII_DII_raw_synthetic_Jan_Jun2026[Net_Flow_Cr], FII_DII_raw_synthetic_Jan_Jun2026[Date], $A3, FII_DII_raw_synthetic_Jan_Jun2026[Entity_Type], "FII", FII_DII_raw_synthetic_Jan_Jun2026[Sector], M$1) -> 0 | N3: =SUMIFS(FII_DII_raw_synthetic_Jan_Jun2026[Net_Flow_Cr], FII_DII_raw_synthetic_Jan_Jun2026[Date], $A3, FII_DII_raw_synthetic_Jan_Jun2026[Entity_Type], "FII", FII_DII_raw_synthetic_Jan_Jun2026[Sector], N$1) -> 0 | ... P3: =SUMIFS(FII_DII_raw_synthetic_Jan_Jun2026[Net_Flow_Cr], FII_DII_raw_synthetic_Jan_Jun2026[Date], $A3, FII_DII_raw_synthetic_Jan_Jun2026[Entity_Type], "FII", FII_DII_raw_synthetic_Jan_Jun2026[Sector], P$1) -> -569.32 | Q3: {=SUMPRODUCT(ABS(G3:P3))} -> 2020.61 | R3: {=LARGE(ABS(G3:P3),1)+LARGE(ABS(G3:P3),2)} -> 1693.09 | S3: =IFERROR(R3/Q3,0) -> 0.83791033 | T3: =IFERROR(_xlfn.XLOOKUP(A3, 'Nifty 50 Historical Data'!A:A, 'Nifty 50 Historical Data'!G:G), "") -> 0.7 | W3: =IF(B3<=-$X$2,"Strong FII Selling",IF(B3>=$X$2,"Strong FII Buying",IF(OR(B3=0,C3=0),"Neutral",IF(SIGN(B3)<>SIGN(C3),"Divergent Flow","Aligned Flow")))) -> Aligned Flow | Y3: =WEEKNUM(A3,2) -> 1 | Z3: Base | AA3: 1 | AB3: 1 | AH3: =AH2+1 -> 46205 | AI3: =$D$129*$AE$2 -> 804.82 | AJ3: =$E$129*$AF$2 -> -396.664
A4: 46026 | B4: =SUMIFS(FII_DII_raw_synthetic_Jan_Jun2026[Net_Flow_Cr], FII_DII_raw_synthetic_Jan_Jun2026[Date], A4, FII_DII_raw_synthetic_Jan_Jun2026[Entity_Type], "FII") -> 1818.05 | C4: =SUMIFS(FII_DII_raw_synthetic_Jan_Jun2026[Net_Flow_Cr], FII_DII_raw_synthetic_Jan_Jun2026[Date], A4, FII_DII_raw_synthetic_Jan_Jun2026[Entity_Type], "DII") -> 38.73 | F4: =ABS(B4)-ABS(C4) -> 1779.32 | G4: =SUMIFS(FII_DII_raw_synthetic_Jan_Jun2026[Net_Flow_Cr], FII_DII_raw_synthetic_Jan_Jun2026[Date], $A4, FII_DII_raw_synthetic_Jan_Jun2026[Entity_Type], "FII", FII_DII_raw_synthetic_Jan_Jun2026[Sector], G$1) -> 0 | H4: =SUMIFS(FII_DII_raw_synthetic_Jan_Jun2026[Net_Flow_Cr], FII_DII_raw_synthetic_Jan_Jun2026[Date], $A4, FII_DII_raw_synthetic_Jan_Jun2026[Entity_Type], "FII", FII_DII_raw_synthetic_Jan_Jun2026[Sector], H$1) -> 0 | I4: =SUMIFS(FII_DII_raw_synthetic_Jan_Jun2026[Net_Flow_Cr], FII_DII_raw_synthetic_Jan_Jun2026[Date], $A4, FII_DII_raw_synthetic_Jan_Jun2026[Entity_Type], "FII", FII_DII_raw_synthetic_Jan_Jun2026[Sector], I$1) -> 0 | J4: =SUMIFS(FII_DII_raw_synthetic_Jan_Jun2026[Net_Flow_Cr], FII_DII_raw_synthetic_Jan_Jun2026[Date], $A4, FII_DII_raw_synthetic_Jan_Jun2026[Entity_Type], "FII", FII_DII_raw_synthetic_Jan_Jun2026[Sector], J$1) -> 1818.05 | K4: =SUMIFS(FII_DII_raw_synthetic_Jan_Jun2026[Net_Flow_Cr], FII_DII_raw_synthetic_Jan_Jun2026[Date], $A4, FII_DII_raw_synthetic_Jan_Jun2026[Entity_Type], "FII", FII_DII_raw_synthetic_Jan_Jun2026[Sector], K$1) -> 0 | L4: =SUMIFS(FII_DII_raw_synthetic_Jan_Jun2026[Net_Flow_Cr], FII_DII_raw_synthetic_Jan_Jun2026[Date], $A4, FII_DII_raw_synthetic_Jan_Jun2026[Entity_Type], "FII", FII_DII_raw_synthetic_Jan_Jun2026[Sector], L$1) -> 0 | M4: =SUMIFS(FII_DII_raw_synthetic_Jan_Jun2026[Net_Flow_Cr], FII_DII_raw_synthetic_Jan_Jun2026[Date], $A4, FII_DII_raw_synthetic_Jan_Jun2026[Entity_Type], "FII", FII_DII_raw_synthetic_Jan_Jun2026[Sector], M$1) -> 0 | N4: =SUMIFS(FII_DII_raw_synthetic_Jan_Jun2026[Net_Flow_Cr], FII_DII_raw_synthetic_Jan_Jun2026[Date], $A4, FII_DII_raw_synthetic_Jan_Jun2026[Entity_Type], "FII", FII_DII_raw_synthetic_Jan_Jun2026[Sector], N$1) -> 0 | ... P4: =SUMIFS(FII_DII_raw_synthetic_Jan_Jun2026[Net_Flow_Cr], FII_DII_raw_synthetic_Jan_Jun2026[Date], $A4, FII_DII_raw_synthetic_Jan_Jun2026[Entity_Type], "FII", FII_DII_raw_synthetic_Jan_Jun2026[Sector], P$1) -> 0 | Q4: {=SUMPRODUCT(ABS(G4:P4))} -> 1818.05 | R4: {=LARGE(ABS(G4:P4),1)+LARGE(ABS(G4:P4),2)} -> 1818.05 | S4: =IFERROR(R4/Q4,0) -> 1 | T4: =IFERROR(_xlfn.XLOOKUP(A4, 'Nifty 50 Historical Data'!A:A, 'Nifty 50 Historical Data'!G:G), "") | W4: =IF(B4<=-$X$2,"Strong FII Selling",IF(B4>=$X$2,"Strong FII Buying",IF(OR(B4=0,C4=0),"Neutral",IF(SIGN(B4)<>SIGN(C4),"Divergent Flow","Aligned Flow")))) -> Aligned Flow | Y4: =WEEKNUM(A4,2) -> 1 | Z4: Bear | AA4: -1.3 | AB4: 0.7 | AH4: =AH3+1 -> 46206 | AI4: =$D$129*$AE$2 -> 804.82 | AJ4: =$E$129*$AF$2 -> -396.664
A5: 46027 | B5: =SUMIFS(FII_DII_raw_synthetic_Jan_Jun2026[Net_Flow_Cr], FII_DII_raw_synthetic_Jan_Jun2026[Date], A5, FII_DII_raw_synthetic_Jan_Jun2026[Entity_Type], "FII") -> -733.3 | C5: =SUMIFS(FII_DII_raw_synthetic_Jan_Jun2026[Net_Flow_Cr], FII_DII_raw_synthetic_Jan_Jun2026[Date], A5, FII_DII_raw_synthetic_Jan_Jun2026[Entity_Type], "DII") -> 779.7 | F5: =ABS(B5)-ABS(C5) -> -46.4 | G5: =SUMIFS(FII_DII_raw_synthetic_Jan_Jun2026[Net_Flow_Cr], FII_DII_raw_synthetic_Jan_Jun2026[Date], $A5, FII_DII_raw_synthetic_Jan_Jun2026[Entity_Type], "FII", FII_DII_raw_synthetic_Jan_Jun2026[Sector], G$1) -> 0 | H5: =SUMIFS(FII_DII_raw_synthetic_Jan_Jun2026[Net_Flow_Cr], FII_DII_raw_synthetic_Jan_Jun2026[Date], $A5, FII_DII_raw_synthetic_Jan_Jun2026[Entity_Type], "FII", FII_DII_raw_synthetic_Jan_Jun2026[Sector], H$1) -> 0 | I5: =SUMIFS(FII_DII_raw_synthetic_Jan_Jun2026[Net_Flow_Cr], FII_DII_raw_synthetic_Jan_Jun2026[Date], $A5, FII_DII_raw_synthetic_Jan_Jun2026[Entity_Type], "FII", FII_DII_raw_synthetic_Jan_Jun2026[Sector], I$1) -> 0 | J5: =SUMIFS(FII_DII_raw_synthetic_Jan_Jun2026[Net_Flow_Cr], FII_DII_raw_synthetic_Jan_Jun2026[Date], $A5, FII_DII_raw_synthetic_Jan_Jun2026[Entity_Type], "FII", FII_DII_raw_synthetic_Jan_Jun2026[Sector], J$1) -> 0 | K5: =SUMIFS(FII_DII_raw_synthetic_Jan_Jun2026[Net_Flow_Cr], FII_DII_raw_synthetic_Jan_Jun2026[Date], $A5, FII_DII_raw_synthetic_Jan_Jun2026[Entity_Type], "FII", FII_DII_raw_synthetic_Jan_Jun2026[Sector], K$1) -> 0 | L5: =SUMIFS(FII_DII_raw_synthetic_Jan_Jun2026[Net_Flow_Cr], FII_DII_raw_synthetic_Jan_Jun2026[Date], $A5, FII_DII_raw_synthetic_Jan_Jun2026[Entity_Type], "FII", FII_DII_raw_synthetic_Jan_Jun2026[Sector], L$1) -> 0 | M5: =SUMIFS(FII_DII_raw_synthetic_Jan_Jun2026[Net_Flow_Cr], FII_DII_raw_synthetic_Jan_Jun2026[Date], $A5, FII_DII_raw_synthetic_Jan_Jun2026[Entity_Type], "FII", FII_DII_raw_synthetic_Jan_Jun2026[Sector], M$1) -> -733.3 | N5: =SUMIFS(FII_DII_raw_synthetic_Jan_Jun2026[Net_Flow_Cr], FII_DII_raw_synthetic_Jan_Jun2026[Date], $A5, FII_DII_raw_synthetic_Jan_Jun2026[Entity_Type], "FII", FII_DII_raw_synthetic_Jan_Jun2026[Sector], N$1) -> 0 | ... P5: =SUMIFS(FII_DII_raw_synthetic_Jan_Jun2026[Net_Flow_Cr], FII_DII_raw_synthetic_Jan_Jun2026[Date], $A5, FII_DII_raw_synthetic_Jan_Jun2026[Entity_Type], "FII", FII_DII_raw_synthetic_Jan_Jun2026[Sector], P$1) -> 0 | Q5: {=SUMPRODUCT(ABS(G5:P5))} -> 733.3 | R5: {=LARGE(ABS(G5:P5),1)+LARGE(ABS(G5:P5),2)} -> 733.3 | S5: =IFERROR(R5/Q5,0) -> 1 | T5: =IFERROR(_xlfn.XLOOKUP(A5, 'Nifty 50 Historical Data'!A:A, 'Nifty 50 Historical Data'!G:G), "") -> -0.3 | W5: =IF(B5<=-$X$2,"Strong FII Selling",IF(B5>=$X$2,"Strong FII Buying",IF(OR(B5=0,C5=0),"Neutral",IF(SIGN(B5)<>SIGN(C5),"Divergent Flow","Aligned Flow")))) -> Divergent Flow | Y5: =WEEKNUM(A5,2) -> 2 | AH5: =AH4+1 -> 46207 | AI5: =$D$129*$AE$2 -> 804.82 | AJ5: =$E$129*$AF$2 -> -396.664
A6: 46028 | B6: =SUMIFS(FII_DII_raw_synthetic_Jan_Jun2026[Net_Flow_Cr], FII_DII_raw_synthetic_Jan_Jun2026[Date], A6, FII_DII_raw_synthetic_Jan_Jun2026[Entity_Type], "FII") -> -3622.57 | C6: =SUMIFS(FII_DII_raw_synthetic_Jan_Jun2026[Net_Flow_Cr], FII_DII_raw_synthetic_Jan_Jun2026[Date], A6, FII_DII_raw_synthetic_Jan_Jun2026[Entity_Type], "DII") -> 3347.9 | D6: =AVERAGE(B2:B6) -> -1216.808 | E6: =AVERAGE(C2:C6) -> 980.74 | F6: =ABS(B6)-ABS(C6) -> 274.67 | G6: =SUMIFS(FII_DII_raw_synthetic_Jan_Jun2026[Net_Flow_Cr], FII_DII_raw_synthetic_Jan_Jun2026[Date], $A6, FII_DII_raw_synthetic_Jan_Jun2026[Entity_Type], "FII", FII_DII_raw_synthetic_Jan_Jun2026[Sector], G$1) -> 0 | H6: =SUMIFS(FII_DII_raw_synthetic_Jan_Jun2026[Net_Flow_Cr], FII_DII_raw_synthetic_Jan_Jun2026[Date], $A6, FII_DII_raw_synthetic_Jan_Jun2026[Entity_Type], "FII", FII_DII_raw_synthetic_Jan_Jun2026[Sector], H$1) -> -309 | I6: =SUMIFS(FII_DII_raw_synthetic_Jan_Jun2026[Net_Flow_Cr], FII_DII_raw_synthetic_Jan_Jun2026[Date], $A6, FII_DII_raw_synthetic_Jan_Jun2026[Entity_Type], "FII", FII_DII_raw_synthetic_Jan_Jun2026[Sector], I$1) -> 0 | J6: =SUMIFS(FII_DII_raw_synthetic_Jan_Jun2026[Net_Flow_Cr], FII_DII_raw_synthetic_Jan_Jun2026[Date], $A6, FII_DII_raw_synthetic_Jan_Jun2026[Entity_Type], "FII", FII_DII_raw_synthetic_Jan_Jun2026[Sector], J$1) -> -914.14 | K6: =SUMIFS(FII_DII_raw_synthetic_Jan_Jun2026[Net_Flow_Cr], FII_DII_raw_synthetic_Jan_Jun2026[Date], $A6, FII_DII_raw_synthetic_Jan_Jun2026[Entity_Type], "FII", FII_DII_raw_synthetic_Jan_Jun2026[Sector], K$1) -> -1736.24 | L6: =SUMIFS(FII_DII_raw_synthetic_Jan_Jun2026[Net_Flow_Cr], FII_DII_raw_synthetic_Jan_Jun2026[Date], $A6, FII_DII_raw_synthetic_Jan_Jun2026[Entity_Type], "FII", FII_DII_raw_synthetic_Jan_Jun2026[Sector], L$1) -> 325.55 | M6: =SUMIFS(FII_DII_raw_synthetic_Jan_Jun2026[Net_Flow_Cr], FII_DII_raw_synthetic_Jan_Jun2026[Date], $A6, FII_DII_raw_synthetic_Jan_Jun2026[Entity_Type], "FII", FII_DII_raw_synthetic_Jan_Jun2026[Sector], M$1) -> 0 | N6: =SUMIFS(FII_DII_raw_synthetic_Jan_Jun2026[Net_Flow_Cr], FII_DII_raw_synthetic_Jan_Jun2026[Date], $A6, FII_DII_raw_synthetic_Jan_Jun2026[Entity_Type], "FII", FII_DII_raw_synthetic_Jan_Jun2026[Sector], N$1) -> 0 | ... P6: =SUMIFS(FII_DII_raw_synthetic_Jan_Jun2026[Net_Flow_Cr], FII_DII_raw_synthetic_Jan_Jun2026[Date], $A6, FII_DII_raw_synthetic_Jan_Jun2026[Entity_Type], "FII", FII_DII_raw_synthetic_Jan_Jun2026[Sector], P$1) -> 0 | Q6: {=SUMPRODUCT(ABS(G6:P6))} -> 4273.67 | R6: {=LARGE(ABS(G6:P6),1)+LARGE(ABS(G6:P6),2)} -> 2724.98 | S6: =IFERROR(R6/Q6,0) -> 0.63762059 | T6: =IFERROR(_xlfn.XLOOKUP(A6, 'Nifty 50 Historical Data'!A:A, 'Nifty 50 Historical Data'!G:G), "") -> -0.27 | W6: =IF(B6<=-$X$2,"Strong FII Selling",IF(B6>=$X$2,"Strong FII Buying",IF(OR(B6=0,C6=0),"Neutral",IF(SIGN(B6)<>SIGN(C6),"Divergent Flow","Aligned Flow")))) -> Strong FII Selling | Y6: =WEEKNUM(A6,2) -> 2 | AH6: =AH5+1 -> 46208 | AI6: =$D$129*$AE$2 -> 804.82 | AJ6: =$E$129*$AF$2 -> -396.664
A7: 46029 | B7: =SUMIFS(FII_DII_raw_synthetic_Jan_Jun2026[Net_Flow_Cr], FII_DII_raw_synthetic_Jan_Jun2026[Date], A7, FII_DII_raw_synthetic_Jan_Jun2026[Entity_Type], "FII") -> -1768.06 | C7: =SUMIFS(FII_DII_raw_synthetic_Jan_Jun2026[Net_Flow_Cr], FII_DII_raw_synthetic_Jan_Jun2026[Date], A7, FII_DII_raw_synthetic_Jan_Jun2026[Entity_Type], "DII") -> -372.19 | D7: =AVERAGE(B3:B7) -> -1134.29 | E7: =AVERAGE(C3:C7) -> 737.212 | F7: =ABS(B7)-ABS(C7) -> 1395.87 | G7: =SUMIFS(FII_DII_raw_synthetic_Jan_Jun2026[Net_Flow_Cr], FII_DII_raw_synthetic_Jan_Jun2026[Date], $A7, FII_DII_raw_synthetic_Jan_Jun2026[Entity_Type], "FII", FII_DII_raw_synthetic_Jan_Jun2026[Sector], G$1) -> 0 | H7: =SUMIFS(FII_DII_raw_synthetic_Jan_Jun2026[Net_Flow_Cr], FII_DII_raw_synthetic_Jan_Jun2026[Date], $A7, FII_DII_raw_synthetic_Jan_Jun2026[Entity_Type], "FII", FII_DII_raw_synthetic_Jan_Jun2026[Sector], H$1) -> 0 | I7: =SUMIFS(FII_DII_raw_synthetic_Jan_Jun2026[Net_Flow_Cr], FII_DII_raw_synthetic_Jan_Jun2026[Date], $A7, FII_DII_raw_synthetic_Jan_Jun2026[Entity_Type], "FII", FII_DII_raw_synthetic_Jan_Jun2026[Sector], I$1) -> 735.2 | J7: =SUMIFS(FII_DII_raw_synthetic_Jan_Jun2026[Net_Flow_Cr], FII_DII_raw_synthetic_Jan_Jun2026[Date], $A7, FII_DII_raw_synthetic_Jan_Jun2026[Entity_Type], "FII", FII_DII_raw_synthetic_Jan_Jun2026[Sector], J$1) -> -906.03 | K7: =SUMIFS(FII_DII_raw_synthetic_Jan_Jun2026[Net_Flow_Cr], FII_DII_raw_synthetic_Jan_Jun2026[Date], $A7, FII_DII_raw_synthetic_Jan_Jun2026[Entity_Type], "FII", FII_DII_raw_synthetic_Jan_Jun2026[Sector], K$1) -> 0 | L7: =SUMIFS(FII_DII_raw_synthetic_Jan_Jun2026[Net_Flow_Cr], FII_DII_raw_synthetic_Jan_Jun2026[Date], $A7, FII_DII_raw_synthetic_Jan_Jun2026[Entity_Type], "FII", FII_DII_raw_synthetic_Jan_Jun2026[Sector], L$1) -> 0 | M7: =SUMIFS(FII_DII_raw_synthetic_Jan_Jun2026[Net_Flow_Cr], FII_DII_raw_synthetic_Jan_Jun2026[Date], $A7, FII_DII_raw_synthetic_Jan_Jun2026[Entity_Type], "FII", FII_DII_raw_synthetic_Jan_Jun2026[Sector], M$1) -> -337.5 | N7: =SUMIFS(FII_DII_raw_synthetic_Jan_Jun2026[Net_Flow_Cr], FII_DII_raw_synthetic_Jan_Jun2026[Date], $A7, FII_DII_raw_synthetic_Jan_Jun2026[Entity_Type], "FII", FII_DII_raw_synthetic_Jan_Jun2026[Sector], N$1) -> 0 | ... P7: =SUMIFS(FII_DII_raw_synthetic_Jan_Jun2026[Net_Flow_Cr], FII_DII_raw_synthetic_Jan_Jun2026[Date], $A7, FII_DII_raw_synthetic_Jan_Jun2026[Entity_Type], "FII", FII_DII_raw_synthetic_Jan_Jun2026[Sector], P$1) -> 0 | Q7: {=SUMPRODUCT(ABS(G7:P7))} -> 3238.46 | R7: {=LARGE(ABS(G7:P7),1)+LARGE(ABS(G7:P7),2)} -> 2165.76 | S7: =IFERROR(R7/Q7,0) -> 0.66876231 | T7: =IFERROR(_xlfn.XLOOKUP(A7, 'Nifty 50 Historical Data'!A:A, 'Nifty 50 Historical Data'!G:G), "") -> -0.14 | W7: =IF(B7<=-$X$2,"Strong FII Selling",IF(B7>=$X$2,"Strong FII Buying",IF(OR(B7=0,C7=0),"Neutral",IF(SIGN(B7)<>SIGN(C7),"Divergent Flow","Aligned Flow")))) -> Aligned Flow | Y7: =WEEKNUM(A7,2) -> 2
A8: 46030 | B8: =SUMIFS(FII_DII_raw_synthetic_Jan_Jun2026[Net_Flow_Cr], FII_DII_raw_synthetic_Jan_Jun2026[Date], A8, FII_DII_raw_synthetic_Jan_Jun2026[Entity_Type], "FII") -> 688.41 | C8: =SUMIFS(FII_DII_raw_synthetic_Jan_Jun2026[Net_Flow_Cr], FII_DII_raw_synthetic_Jan_Jun2026[Date], A8, FII_DII_raw_synthetic_Jan_Jun2026[Entity_Type], "DII") -> -1471.16 | D8: =AVERAGE(B4:B8) -> -723.494 | E8: =AVERAGE(C4:C8) -> 464.596 | F8: =ABS(B8)-ABS(C8) -> -782.75 | G8: =SUMIFS(FII_DII_raw_synthetic_Jan_Jun2026[Net_Flow_Cr], FII_DII_raw_synthetic_Jan_Jun2026[Date], $A8, FII_DII_raw_synthetic_Jan_Jun2026[Entity_Type], "FII", FII_DII_raw_synthetic_Jan_Jun2026[Sector], G$1) -> 0 | H8: =SUMIFS(FII_DII_raw_synthetic_Jan_Jun2026[Net_Flow_Cr], FII_DII_raw_synthetic_Jan_Jun2026[Date], $A8, FII_DII_raw_synthetic_Jan_Jun2026[Entity_Type], "FII", FII_DII_raw_synthetic_Jan_Jun2026[Sector], H$1) -> 63.68 | I8: =SUMIFS(FII_DII_raw_synthetic_Jan_Jun2026[Net_Flow_Cr], FII_DII_raw_synthetic_Jan_Jun2026[Date], $A8, FII_DII_raw_synthetic_Jan_Jun2026[Entity_Type], "FII", FII_DII_raw_synthetic_Jan_Jun2026[Sector], I$1) -> 0 | J8: =SUMIFS(FII_DII_raw_synthetic_Jan_Jun2026[Net_Flow_Cr], FII_DII_raw_synthetic_Jan_Jun2026[Date], $A8, FII_DII_raw_synthetic_Jan_Jun2026[Entity_Type], "FII", FII_DII_raw_synthetic_Jan_Jun2026[Sector], J$1) -> 0 | K8: =SUMIFS(FII_DII_raw_synthetic_Jan_Jun2026[Net_Flow_Cr], FII_DII_raw_synthetic_Jan_Jun2026[Date], $A8, FII_DII_raw_synthetic_Jan_Jun2026[Entity_Type], "FII", FII_DII_raw_synthetic_Jan_Jun2026[Sector], K$1) -> 0 | L8: =SUMIFS(FII_DII_raw_synthetic_Jan_Jun2026[Net_Flow_Cr], FII_DII_raw_synthetic_Jan_Jun2026[Date], $A8, FII_DII_raw_synthetic_Jan_Jun2026[Entity_Type], "FII", FII_DII_raw_synthetic_Jan_Jun2026[Sector], L$1) -> 0 | M8: =SUMIFS(FII_DII_raw_synthetic_Jan_Jun2026[Net_Flow_Cr], FII_DII_raw_synthetic_Jan_Jun2026[Date], $A8, FII_DII_raw_synthetic_Jan_Jun2026[Entity_Type], "FII", FII_DII_raw_synthetic_Jan_Jun2026[Sector], M$1) -> 435.34 | N8: =SUMIFS(FII_DII_raw_synthetic_Jan_Jun2026[Net_Flow_Cr], FII_DII_raw_synthetic_Jan_Jun2026[Date], $A8, FII_DII_raw_synthetic_Jan_Jun2026[Entity_Type], "FII", FII_DII_raw_synthetic_Jan_Jun2026[Sector], N$1) -> -443.55 | ... P8: =SUMIFS(FII_DII_raw_synthetic_Jan_Jun2026[Net_Flow_Cr], FII_DII_raw_synthetic_Jan_Jun2026[Date], $A8, FII_DII_raw_synthetic_Jan_Jun2026[Entity_Type], "FII", FII_DII_raw_synthetic_Jan_Jun2026[Sector], P$1) -> 632.94 | Q8: {=SUMPRODUCT(ABS(G8:P8))} -> 1575.51 | R8: {=LARGE(ABS(G8:P8),1)+LARGE(ABS(G8:P8),2)} -> 1076.49 | S8: =IFERROR(R8/Q8,0) -> 0.68326447 | T8: =IFERROR(_xlfn.XLOOKUP(A8, 'Nifty 50 Historical Data'!A:A, 'Nifty 50 Historical Data'!G:G), "") -> -1.01 | W8: =IF(B8<=-$X$2,"Strong FII Selling",IF(B8>=$X$2,"Strong FII Buying",IF(OR(B8=0,C8=0),"Neutral",IF(SIGN(B8)<>SIGN(C8),"Divergent Flow","Aligned Flow")))) -> Divergent Flow | Y8: =WEEKNUM(A8,2) -> 2
A9: 46031 | B9: =SUMIFS(FII_DII_raw_synthetic_Jan_Jun2026[Net_Flow_Cr], FII_DII_raw_synthetic_Jan_Jun2026[Date], A9, FII_DII_raw_synthetic_Jan_Jun2026[Entity_Type], "FII") -> -1508.47 | C9: =SUMIFS(FII_DII_raw_synthetic_Jan_Jun2026[Net_Flow_Cr], FII_DII_raw_synthetic_Jan_Jun2026[Date], A9, FII_DII_raw_synthetic_Jan_Jun2026[Entity_Type], "DII") -> -452.34 | D9: =AVERAGE(B5:B9) -> -1388.798 | E9: =AVERAGE(C5:C9) -> 366.382 | F9: =ABS(B9)-ABS(C9) -> 1056.13 | G9: =SUMIFS(FII_DII_raw_synthetic_Jan_Jun2026[Net_Flow_Cr], FII_DII_raw_synthetic_Jan_Jun2026[Date], $A9, FII_DII_raw_synthetic_Jan_Jun2026[Entity_Type], "FII", FII_DII_raw_synthetic_Jan_Jun2026[Sector], G$1) -> 0 | H9: =SUMIFS(FII_DII_raw_synthetic_Jan_Jun2026[Net_Flow_Cr], FII_DII_raw_synthetic_Jan_Jun2026[Date], $A9, FII_DII_raw_synthetic_Jan_Jun2026[Entity_Type], "FII", FII_DII_raw_synthetic_Jan_Jun2026[Sector], H$1) -> -1245.12 | I9: =SUMIFS(FII_DII_raw_synthetic_Jan_Jun2026[Net_Flow_Cr], FII_DII_raw_synthetic_Jan_Jun2026[Date], $A9, FII_DII_raw_synthetic_Jan_Jun2026[Entity_Type], "FII", FII_DII_raw_synthetic_Jan_Jun2026[Sector], I$1) -> 0 | J9: =SUMIFS(FII_DII_raw_synthetic_Jan_Jun2026[Net_Flow_Cr], FII_DII_raw_synthetic_Jan_Jun2026[Date], $A9, FII_DII_raw_synthetic_Jan_Jun2026[Entity_Type], "FII", FII_DII_raw_synthetic_Jan_Jun2026[Sector], J$1) -> -152.77 | K9: =SUMIFS(FII_DII_raw_synthetic_Jan_Jun2026[Net_Flow_Cr], FII_DII_raw_synthetic_Jan_Jun2026[Date], $A9, FII_DII_raw_synthetic_Jan_Jun2026[Entity_Type], "FII", FII_DII_raw_synthetic_Jan_Jun2026[Sector], K$1) -> 0 | L9: =SUMIFS(FII_DII_raw_synthetic_Jan_Jun2026[Net_Flow_Cr], FII_DII_raw_synthetic_Jan_Jun2026[Date], $A9, FII_DII_raw_synthetic_Jan_Jun2026[Entity_Type], "FII", FII_DII_raw_synthetic_Jan_Jun2026[Sector], L$1) -> 0 | M9: =SUMIFS(FII_DII_raw_synthetic_Jan_Jun2026[Net_Flow_Cr], FII_DII_raw_synthetic_Jan_Jun2026[Date], $A9, FII_DII_raw_synthetic_Jan_Jun2026[Entity_Type], "FII", FII_DII_raw_synthetic_Jan_Jun2026[Sector], M$1) -> -1417.34 | N9: =SUMIFS(FII_DII_raw_synthetic_Jan_Jun2026[Net_Flow_Cr], FII_DII_raw_synthetic_Jan_Jun2026[Date], $A9, FII_DII_raw_synthetic_Jan_Jun2026[Entity_Type], "FII", FII_DII_raw_synthetic_Jan_Jun2026[Sector], N$1) -> 0 | ... P9: =SUMIFS(FII_DII_raw_synthetic_Jan_Jun2026[Net_Flow_Cr], FII_DII_raw_synthetic_Jan_Jun2026[Date], $A9, FII_DII_raw_synthetic_Jan_Jun2026[Entity_Type], "FII", FII_DII_raw_synthetic_Jan_Jun2026[Sector], P$1) -> 0 | Q9: {=SUMPRODUCT(ABS(G9:P9))} -> 4121.99 | R9: {=LARGE(ABS(G9:P9),1)+LARGE(ABS(G9:P9),2)} -> 2724.1 | S9: =IFERROR(R9/Q9,0) -> 0.66087011 | T9: =IFERROR(_xlfn.XLOOKUP(A9, 'Nifty 50 Historical Data'!A:A, 'Nifty 50 Historical Data'!G:G), "") -> -0.75 | W9: =IF(B9<=-$X$2,"Strong FII Selling",IF(B9>=$X$2,"Strong FII Buying",IF(OR(B9=0,C9=0),"Neutral",IF(SIGN(B9)<>SIGN(C9),"Divergent Flow","Aligned Flow")))) -> Aligned Flow | Y9: =WEEKNUM(A9,2) -> 2
A10: 46034 | B10: =SUMIFS(FII_DII_raw_synthetic_Jan_Jun2026[Net_Flow_Cr], FII_DII_raw_synthetic_Jan_Jun2026[Date], A10, FII_DII_raw_synthetic_Jan_Jun2026[Entity_Type], "FII") -> -1801.5 | C10: =SUMIFS(FII_DII_raw_synthetic_Jan_Jun2026[Net_Flow_Cr], FII_DII_raw_synthetic_Jan_Jun2026[Date], A10, FII_DII_raw_synthetic_Jan_Jun2026[Entity_Type], "DII") -> 929.86 | D10: =AVERAGE(B6:B10) -> -1602.438 | E10: =AVERAGE(C6:C10) -> 396.414 | F10: =ABS(B10)-ABS(C10) -> 871.64 | G10: =SUMIFS(FII_DII_raw_synthetic_Jan_Jun2026[Net_Flow_Cr], FII_DII_raw_synthetic_Jan_Jun2026[Date], $A10, FII_DII_raw_synthetic_Jan_Jun2026[Entity_Type], "FII", FII_DII_raw_synthetic_Jan_Jun2026[Sector], G$1) -> -1386.78 | H10: =SUMIFS(FII_DII_raw_synthetic_Jan_Jun2026[Net_Flow_Cr], FII_DII_raw_synthetic_Jan_Jun2026[Date], $A10, FII_DII_raw_synthetic_Jan_Jun2026[Entity_Type], "FII", FII_DII_raw_synthetic_Jan_Jun2026[Sector], H$1) -> 0 | I10: =SUMIFS(FII_DII_raw_synthetic_Jan_Jun2026[Net_Flow_Cr], FII_DII_raw_synthetic_Jan_Jun2026[Date], $A10, FII_DII_raw_synthetic_Jan_Jun2026[Entity_Type], "FII", FII_DII_raw_synthetic_Jan_Jun2026[Sector], I$1) -> -883.49 | J10: =SUMIFS(FII_DII_raw_synthetic_Jan_Jun2026[Net_Flow_Cr], FII_DII_raw_synthetic_Jan_Jun2026[Date], $A10, FII_DII_raw_synthetic_Jan_Jun2026[Entity_Type], "FII", FII_DII_raw_synthetic_Jan_Jun2026[Sector], J$1) -> 0 | K10: =SUMIFS(FII_DII_raw_synthetic_Jan_Jun2026[Net_Flow_Cr], FII_DII_raw_synthetic_Jan_Jun2026[Date], $A10, FII_DII_raw_synthetic_Jan_Jun2026[Entity_Type], "FII", FII_DII_raw_synthetic_Jan_Jun2026[Sector], K$1) -> 0 | L10: =SUMIFS(FII_DII_raw_synthetic_Jan_Jun2026[Net_Flow_Cr], FII_DII_raw_synthetic_Jan_Jun2026[Date], $A10, FII_DII_raw_synthetic_Jan_Jun2026[Entity_Type], "FII", FII_DII_raw_synthetic_Jan_Jun2026[Sector], L$1) -> 0 | M10: =SUMIFS(FII_DII_raw_synthetic_Jan_Jun2026[Net_Flow_Cr], FII_DII_raw_synthetic_Jan_Jun2026[Date], $A10, FII_DII_raw_synthetic_Jan_Jun2026[Entity_Type], "FII", FII_DII_raw_synthetic_Jan_Jun2026[Sector], M$1) -> 0 | N10: =SUMIFS(FII_DII_raw_synthetic_Jan_Jun2026[Net_Flow_Cr], FII_DII_raw_synthetic_Jan_Jun2026[Date], $A10, FII_DII_raw_synthetic_Jan_Jun2026[Entity_Type], "FII", FII_DII_raw_synthetic_Jan_Jun2026[Sector], N$1) -> -1148.22 | ... P10: =SUMIFS(FII_DII_raw_synthetic_Jan_Jun2026[Net_Flow_Cr], FII_DII_raw_synthetic_Jan_Jun2026[Date], $A10, FII_DII_raw_synthetic_Jan_Jun2026[Entity_Type], "FII", FII_DII_raw_synthetic_Jan_Jun2026[Sector], P$1) -> 0 | Q10: {=SUMPRODUCT(ABS(G10:P10))} -> 5035.48 | R10: {=LARGE(ABS(G10:P10),1)+LARGE(ABS(G10:P10),2)} -> 3003.77 | S10: =IFERROR(R10/Q10,0) -> 0.59652109 | T10: =IFERROR(_xlfn.XLOOKUP(A10, 'Nifty 50 Historical Data'!A:A, 'Nifty 50 Historical Data'!G:G), "") -> 0.42 | W10: =IF(B10<=-$X$2,"Strong FII Selling",IF(B10>=$X$2,"Strong FII Buying",IF(OR(B10=0,C10=0),"Neutral",IF(SIGN(B10)<>SIGN(C10),"Divergent Flow","Aligned Flow")))) -> Divergent Flow | Y10: =WEEKNUM(A10,2) -> 3
A11: 46035 | B11: =SUMIFS(FII_DII_raw_synthetic_Jan_Jun2026[Net_Flow_Cr], FII_DII_raw_synthetic_Jan_Jun2026[Date], A11, FII_DII_raw_synthetic_Jan_Jun2026[Entity_Type], "FII") -> 1150.59 | C11: =SUMIFS(FII_DII_raw_synthetic_Jan_Jun2026[Net_Flow_Cr], FII_DII_raw_synthetic_Jan_Jun2026[Date], A11, FII_DII_raw_synthetic_Jan_Jun2026[Entity_Type], "DII") -> -2409.58 | D11: =AVERAGE(B7:B11) -> -647.806 | E11: =AVERAGE(C7:C11) -> -755.082 | F11: =ABS(B11)-ABS(C11) -> -1258.99 | G11: =SUMIFS(FII_DII_raw_synthetic_Jan_Jun2026[Net_Flow_Cr], FII_DII_raw_synthetic_Jan_Jun2026[Date], $A11, FII_DII_raw_synthetic_Jan_Jun2026[Entity_Type], "FII", FII_DII_raw_synthetic_Jan_Jun2026[Sector], G$1) -> 0 | H11: =SUMIFS(FII_DII_raw_synthetic_Jan_Jun2026[Net_Flow_Cr], FII_DII_raw_synthetic_Jan_Jun2026[Date], $A11, FII_DII_raw_synthetic_Jan_Jun2026[Entity_Type], "FII", FII_DII_raw_synthetic_Jan_Jun2026[Sector], H$1) -> 0 | I11: =SUMIFS(FII_DII_raw_synthetic_Jan_Jun2026[Net_Flow_Cr], FII_DII_raw_synthetic_Jan_Jun2026[Date], $A11, FII_DII_raw_synthetic_Jan_Jun2026[Entity_Type], "FII", FII_DII_raw_synthetic_Jan_Jun2026[Sector], I$1) -> 1256.68 | J11: =SUMIFS(FII_DII_raw_synthetic_Jan_Jun2026[Net_Flow_Cr], FII_DII_raw_synthetic_Jan_Jun2026[Date], $A11, FII_DII_raw_synthetic_Jan_Jun2026[Entity_Type], "FII", FII_DII_raw_synthetic_Jan_Jun2026[Sector], J$1) -> 129.8 | K11: =SUMIFS(FII_DII_raw_synthetic_Jan_Jun2026[Net_Flow_Cr], FII_DII_raw_synthetic_Jan_Jun2026[Date], $A11, FII_DII_raw_synthetic_Jan_Jun2026[Entity_Type], "FII", FII_DII_raw_synthetic_Jan_Jun2026[Sector], K$1) -> 0 | L11: =SUMIFS(FII_DII_raw_synthetic_Jan_Jun2026[Net_Flow_Cr], FII_DII_raw_synthetic_Jan_Jun2026[Date], $A11, FII_DII_raw_synthetic_Jan_Jun2026[Entity_Type], "FII", FII_DII_raw_synthetic_Jan_Jun2026[Sector], L$1) -> 0 | M11: =SUMIFS(FII_DII_raw_synthetic_Jan_Jun2026[Net_Flow_Cr], FII_DII_raw_synthetic_Jan_Jun2026[Date], $A11, FII_DII_raw_synthetic_Jan_Jun2026[Entity_Type], "FII", FII_DII_raw_synthetic_Jan_Jun2026[Sector], M$1) -> -529.73 | N11: =SUMIFS(FII_DII_raw_synthetic_Jan_Jun2026[Net_Flow_Cr], FII_DII_raw_synthetic_Jan_Jun2026[Date], $A11, FII_DII_raw_synthetic_Jan_Jun2026[Entity_Type], "FII", FII_DII_raw_synthetic_Jan_Jun2026[Sector], N$1) -> 293.84 | ... P11: =SUMIFS(FII_DII_raw_synthetic_Jan_Jun2026[Net_Flow_Cr], FII_DII_raw_synthetic_Jan_Jun2026[Date], $A11, FII_DII_raw_synthetic_Jan_Jun2026[Entity_Type], "FII", FII_DII_raw_synthetic_Jan_Jun2026[Sector], P$1) -> 0 | Q11: {=SUMPRODUCT(ABS(G11:P11))} -> 2210.05 | R11: {=LARGE(ABS(G11:P11),1)+LARGE(ABS(G11:P11),2)} -> 1786.41 | S11: =IFERROR(R11/Q11,0) -> 0.80831203 | T11: =IFERROR(_xlfn.XLOOKUP(A11, 'Nifty 50 Historical Data'!A:A, 'Nifty 50 Historical Data'!G:G), "") -> -0.22 | W11: =IF(B11<=-$X$2,"Strong FII Selling",IF(B11>=$X$2,"Strong FII Buying",IF(OR(B11=0,C11=0),"Neutral",IF(SIGN(B11)<>SIGN(C11),"Divergent Flow","Aligned Flow")))) -> Divergent Flow | Y11: =WEEKNUM(A11,2) -> 3
A12: 46036 | B12: =SUMIFS(FII_DII_raw_synthetic_Jan_Jun2026[Net_Flow_Cr], FII_DII_raw_synthetic_Jan_Jun2026[Date], A12, FII_DII_raw_synthetic_Jan_Jun2026[Entity_Type], "FII") -> 435.57 | C12: =SUMIFS(FII_DII_raw_synthetic_Jan_Jun2026[Net_Flow_Cr], FII_DII_raw_synthetic_Jan_Jun2026[Date], A12, FII_DII_raw_synthetic_Jan_Jun2026[Entity_Type], "DII") -> -3322.44 | D12: =AVERAGE(B8:B12) -> -207.08 | E12: =AVERAGE(C8:C12) -> -1345.132 | F12: =ABS(B12)-ABS(C12) -> -2886.87 | G12: =SUMIFS(FII_DII_raw_synthetic_Jan_Jun2026[Net_Flow_Cr], FII_DII_raw_synthetic_Jan_Jun2026[Date], $A12, FII_DII_raw_synthetic_Jan_Jun2026[Entity_Type], "FII", FII_DII_raw_synthetic_Jan_Jun2026[Sector], G$1) -> 0 | H12: =SUMIFS(FII_DII_raw_synthetic_Jan_Jun2026[Net_Flow_Cr], FII_DII_raw_synthetic_Jan_Jun2026[Date], $A12, FII_DII_raw_synthetic_Jan_Jun2026[Entity_Type], "FII", FII_DII_raw_synthetic_Jan_Jun2026[Sector], H$1) -> -383.95 | I12: =SUMIFS(FII_DII_raw_synthetic_Jan_Jun2026[Net_Flow_Cr], FII_DII_raw_synthetic_Jan_Jun2026[Date], $A12, FII_DII_raw_synthetic_Jan_Jun2026[Entity_Type], "FII", FII_DII_raw_synthetic_Jan_Jun2026[Sector], I$1) -> 0 | J12: =SUMIFS(FII_DII_raw_synthetic_Jan_Jun2026[Net_Flow_Cr], FII_DII_raw_synthetic_Jan_Jun2026[Date], $A12, FII_DII_raw_synthetic_Jan_Jun2026[Entity_Type], "FII", FII_DII_raw_synthetic_Jan_Jun2026[Sector], J$1) -> -656.69 | K12: =SUMIFS(FII_DII_raw_synthetic_Jan_Jun2026[Net_Flow_Cr], FII_DII_raw_synthetic_Jan_Jun2026[Date], $A12, FII_DII_raw_synthetic_Jan_Jun2026[Entity_Type], "FII", FII_DII_raw_synthetic_Jan_Jun2026[Sector], K$1) -> 0 | L12: =SUMIFS(FII_DII_raw_synthetic_Jan_Jun2026[Net_Flow_Cr], FII_DII_raw_synthetic_Jan_Jun2026[Date], $A12, FII_DII_raw_synthetic_Jan_Jun2026[Entity_Type], "FII", FII_DII_raw_synthetic_Jan_Jun2026[Sector], L$1) -> 0 | M12: =SUMIFS(FII_DII_raw_synthetic_Jan_Jun2026[Net_Flow_Cr], FII_DII_raw_synthetic_Jan_Jun2026[Date], $A12, FII_DII_raw_synthetic_Jan_Jun2026[Entity_Type], "FII", FII_DII_raw_synthetic_Jan_Jun2026[Sector], M$1) -> 0 | N12: =SUMIFS(FII_DII_raw_synthetic_Jan_Jun2026[Net_Flow_Cr], FII_DII_raw_synthetic_Jan_Jun2026[Date], $A12, FII_DII_raw_synthetic_Jan_Jun2026[Entity_Type], "FII", FII_DII_raw_synthetic_Jan_Jun2026[Sector], N$1) -> 1476.21 | ... P12: =SUMIFS(FII_DII_raw_synthetic_Jan_Jun2026[Net_Flow_Cr], FII_DII_raw_synthetic_Jan_Jun2026[Date], $A12, FII_DII_raw_synthetic_Jan_Jun2026[Entity_Type], "FII", FII_DII_raw_synthetic_Jan_Jun2026[Sector], P$1) -> 0 | Q12: {=SUMPRODUCT(ABS(G12:P12))} -> 2516.85 | R12: {=LARGE(ABS(G12:P12),1)+LARGE(ABS(G12:P12),2)} -> 2132.9 | S12: =IFERROR(R12/Q12,0) -> 0.8474482 | T12: =IFERROR(_xlfn.XLOOKUP(A12, 'Nifty 50 Historical Data'!A:A, 'Nifty 50 Historical Data'!G:G), "") -> -0.26 | W12: =IF(B12<=-$X$2,"Strong FII Selling",IF(B12>=$X$2,"Strong FII Buying",IF(OR(B12=0,C12=0),"Neutral",IF(SIGN(B12)<>SIGN(C12),"Divergent Flow","Aligned Flow")))) -> Divergent Flow | Y12: =WEEKNUM(A12,2) -> 3
A13: 46037 | B13: =SUMIFS(FII_DII_raw_synthetic_Jan_Jun2026[Net_Flow_Cr], FII_DII_raw_synthetic_Jan_Jun2026[Date], A13, FII_DII_raw_synthetic_Jan_Jun2026[Entity_Type], "FII") -> -2230.2 | C13: =SUMIFS(FII_DII_raw_synthetic_Jan_Jun2026[Net_Flow_Cr], FII_DII_raw_synthetic_Jan_Jun2026[Date], A13, FII_DII_raw_synthetic_Jan_Jun2026[Entity_Type], "DII") -> -1759.25 | D13: =AVERAGE(B9:B13) -> -790.802 | E13: =AVERAGE(C9:C13) -> -1402.75 | F13: =ABS(B13)-ABS(C13) -> 470.95 | G13: =SUMIFS(FII_DII_raw_synthetic_Jan_Jun2026[Net_Flow_Cr], FII_DII_raw_synthetic_Jan_Jun2026[Date], $A13, FII_DII_raw_synthetic_Jan_Jun2026[Entity_Type], "FII", FII_DII_raw_synthetic_Jan_Jun2026[Sector], G$1) -> 0 | H13: =SUMIFS(FII_DII_raw_synthetic_Jan_Jun2026[Net_Flow_Cr], FII_DII_raw_synthetic_Jan_Jun2026[Date], $A13, FII_DII_raw_synthetic_Jan_Jun2026[Entity_Type], "FII", FII_DII_raw_synthetic_Jan_Jun2026[Sector], H$1) -> -714.02 | I13: =SUMIFS(FII_DII_raw_synthetic_Jan_Jun2026[Net_Flow_Cr], FII_DII_raw_synthetic_Jan_Jun2026[Date], $A13, FII_DII_raw_synthetic_Jan_Jun2026[Entity_Type], "FII", FII_DII_raw_synthetic_Jan_Jun2026[Sector], I$1) -> 902.02 | J13: =SUMIFS(FII_DII_raw_synthetic_Jan_Jun2026[Net_Flow_Cr], FII_DII_raw_synthetic_Jan_Jun2026[Date], $A13, FII_DII_raw_synthetic_Jan_Jun2026[Entity_Type], "FII", FII_DII_raw_synthetic_Jan_Jun2026[Sector], J$1) -> 0 | K13: =SUMIFS(FII_DII_raw_synthetic_Jan_Jun2026[Net_Flow_Cr], FII_DII_raw_synthetic_Jan_Jun2026[Date], $A13, FII_DII_raw_synthetic_Jan_Jun2026[Entity_Type], "FII", FII_DII_raw_synthetic_Jan_Jun2026[Sector], K$1) -> 0 | L13: =SUMIFS(FII_DII_raw_synthetic_Jan_Jun2026[Net_Flow_Cr], FII_DII_raw_synthetic_Jan_Jun2026[Date], $A13, FII_DII_raw_synthetic_Jan_Jun2026[Entity_Type], "FII", FII_DII_raw_synthetic_Jan_Jun2026[Sector], L$1) -> 0 | M13: =SUMIFS(FII_DII_raw_synthetic_Jan_Jun2026[Net_Flow_Cr], FII_DII_raw_synthetic_Jan_Jun2026[Date], $A13, FII_DII_raw_synthetic_Jan_Jun2026[Entity_Type], "FII", FII_DII_raw_synthetic_Jan_Jun2026[Sector], M$1) -> -1579.32 | N13: =SUMIFS(FII_DII_raw_synthetic_Jan_Jun2026[Net_Flow_Cr], FII_DII_raw_synthetic_Jan_Jun2026[Date], $A13, FII_DII_raw_synthetic_Jan_Jun2026[Entity_Type], "FII", FII_DII_raw_synthetic_Jan_Jun2026[Sector], N$1) -> 0 | ... P13: =SUMIFS(FII_DII_raw_synthetic_Jan_Jun2026[Net_Flow_Cr], FII_DII_raw_synthetic_Jan_Jun2026[Date], $A13, FII_DII_raw_synthetic_Jan_Jun2026[Entity_Type], "FII", FII_DII_raw_synthetic_Jan_Jun2026[Sector], P$1) -> -838.88 | Q13: {=SUMPRODUCT(ABS(G13:P13))} -> 4034.24 | R13: {=LARGE(ABS(G13:P13),1)+LARGE(ABS(G13:P13),2)} -> 2481.34 | S13: =IFERROR(R13/Q13,0) -> 0.61507 | T13: =IFERROR(_xlfn.XLOOKUP(A13, 'Nifty 50 Historical Data'!A:A, 'Nifty 50 Historical Data'!G:G), "") | W13: =IF(B13<=-$X$2,"Strong FII Selling",IF(B13>=$X$2,"Strong FII Buying",IF(OR(B13=0,C13=0),"Neutral",IF(SIGN(B13)<>SIGN(C13),"Divergent Flow","Aligned Flow")))) -> Strong FII Selling | Y13: =WEEKNUM(A13,2) -> 3
A14: 46038 | B14: =SUMIFS(FII_DII_raw_synthetic_Jan_Jun2026[Net_Flow_Cr], FII_DII_raw_synthetic_Jan_Jun2026[Date], A14, FII_DII_raw_synthetic_Jan_Jun2026[Entity_Type], "FII") -> -1653.04 | C14: =SUMIFS(FII_DII_raw_synthetic_Jan_Jun2026[Net_Flow_Cr], FII_DII_raw_synthetic_Jan_Jun2026[Date], A14, FII_DII_raw_synthetic_Jan_Jun2026[Entity_Type], "DII") -> -236.68 | D14: =AVERAGE(B10:B14) -> -819.716 | E14: =AVERAGE(C10:C14) -> -1359.618 | F14: =ABS(B14)-ABS(C14) -> 1416.36 | G14: =SUMIFS(FII_DII_raw_synthetic_Jan_Jun2026[Net_Flow_Cr], FII_DII_raw_synthetic_Jan_Jun2026[Date], $A14, FII_DII_raw_synthetic_Jan_Jun2026[Entity_Type], "FII", FII_DII_raw_synthetic_Jan_Jun2026[Sector], G$1) -> 0 | H14: =SUMIFS(FII_DII_raw_synthetic_Jan_Jun2026[Net_Flow_Cr], FII_DII_raw_synthetic_Jan_Jun2026[Date], $A14, FII_DII_raw_synthetic_Jan_Jun2026[Entity_Type], "FII", FII_DII_raw_synthetic_Jan_Jun2026[Sector], H$1) -> 0 | I14: =SUMIFS(FII_DII_raw_synthetic_Jan_Jun2026[Net_Flow_Cr], FII_DII_raw_synthetic_Jan_Jun2026[Date], $A14, FII_DII_raw_synthetic_Jan_Jun2026[Entity_Type], "FII", FII_DII_raw_synthetic_Jan_Jun2026[Sector], I$1) -> -286.79 | J14: =SUMIFS(FII_DII_raw_synthetic_Jan_Jun2026[Net_Flow_Cr], FII_DII_raw_synthetic_Jan_Jun2026[Date], $A14, FII_DII_raw_synthetic_Jan_Jun2026[Entity_Type], "FII", FII_DII_raw_synthetic_Jan_Jun2026[Sector], J$1) -> -1369.52 | K14: =SUMIFS(FII_DII_raw_synthetic_Jan_Jun2026[Net_Flow_Cr], FII_DII_raw_synthetic_Jan_Jun2026[Date], $A14, FII_DII_raw_synthetic_Jan_Jun2026[Entity_Type], "FII", FII_DII_raw_synthetic_Jan_Jun2026[Sector], K$1) -> 0 | L14: =SUMIFS(FII_DII_raw_synthetic_Jan_Jun2026[Net_Flow_Cr], FII_DII_raw_synthetic_Jan_Jun2026[Date], $A14, FII_DII_raw_synthetic_Jan_Jun2026[Entity_Type], "FII", FII_DII_raw_synthetic_Jan_Jun2026[Sector], L$1) -> 0 | M14: =SUMIFS(FII_DII_raw_synthetic_Jan_Jun2026[Net_Flow_Cr], FII_DII_raw_synthetic_Jan_Jun2026[Date], $A14, FII_DII_raw_synthetic_Jan_Jun2026[Entity_Type], "FII", FII_DII_raw_synthetic_Jan_Jun2026[Sector], M$1) -> 3.27 | N14: =SUMIFS(FII_DII_raw_synthetic_Jan_Jun2026[Net_Flow_Cr], FII_DII_raw_synthetic_Jan_Jun2026[Date], $A14, FII_DII_raw_synthetic_Jan_Jun2026[Entity_Type], "FII", FII_DII_raw_synthetic_Jan_Jun2026[Sector], N$1) -> 0 | ... P14: =SUMIFS(FII_DII_raw_synthetic_Jan_Jun2026[Net_Flow_Cr], FII_DII_raw_synthetic_Jan_Jun2026[Date], $A14, FII_DII_raw_synthetic_Jan_Jun2026[Entity_Type], "FII", FII_DII_raw_synthetic_Jan_Jun2026[Sector], P$1) -> 0 | Q14: {=SUMPRODUCT(ABS(G14:P14))} -> 1659.58 | R14: {=LARGE(ABS(G14:P14),1)+LARGE(ABS(G14:P14),2)} -> 1656.31 | S14: =IFERROR(R14/Q14,0) -> 0.99802962 | T14: =IFERROR(_xlfn.XLOOKUP(A14, 'Nifty 50 Historical Data'!A:A, 'Nifty 50 Historical Data'!G:G), "") -> 0.11 | W14: =IF(B14<=-$X$2,"Strong FII Selling",IF(B14>=$X$2,"Strong FII Buying",IF(OR(B14=0,C14=0),"Neutral",IF(SIGN(B14)<>SIGN(C14),"Divergent Flow","Aligned Flow")))) -> Aligned Flow | Y14: =WEEKNUM(A14,2) -> 3
A15: 46041 | B15: =SUMIFS(FII_DII_raw_synthetic_Jan_Jun2026[Net_Flow_Cr], FII_DII_raw_synthetic_Jan_Jun2026[Date], A15, FII_DII_raw_synthetic_Jan_Jun2026[Entity_Type], "FII") -> -228.08 | C15: =SUMIFS(FII_DII_raw_synthetic_Jan_Jun2026[Net_Flow_Cr], FII_DII_raw_synthetic_Jan_Jun2026[Date], A15, FII_DII_raw_synthetic_Jan_Jun2026[Entity_Type], "DII") -> 2934.56 | D15: =AVERAGE(B11:B15) -> -505.032 | E15: =AVERAGE(C11:C15) -> -958.678 | F15: =ABS(B15)-ABS(C15) -> -2706.48 | G15: =SUMIFS(FII_DII_raw_synthetic_Jan_Jun2026[Net_Flow_Cr], FII_DII_raw_synthetic_Jan_Jun2026[Date], $A15, FII_DII_raw_synthetic_Jan_Jun2026[Entity_Type], "FII", FII_DII_raw_synthetic_Jan_Jun2026[Sector], G$1) -> 0 | H15: =SUMIFS(FII_DII_raw_synthetic_Jan_Jun2026[Net_Flow_Cr], FII_DII_raw_synthetic_Jan_Jun2026[Date], $A15, FII_DII_raw_synthetic_Jan_Jun2026[Entity_Type], "FII", FII_DII_raw_synthetic_Jan_Jun2026[Sector], H$1) -> 0 | I15: =SUMIFS(FII_DII_raw_synthetic_Jan_Jun2026[Net_Flow_Cr], FII_DII_raw_synthetic_Jan_Jun2026[Date], $A15, FII_DII_raw_synthetic_Jan_Jun2026[Entity_Type], "FII", FII_DII_raw_synthetic_Jan_Jun2026[Sector], I$1) -> 0 | J15: =SUMIFS(FII_DII_raw_synthetic_Jan_Jun2026[Net_Flow_Cr], FII_DII_raw_synthetic_Jan_Jun2026[Date], $A15, FII_DII_raw_synthetic_Jan_Jun2026[Entity_Type], "FII", FII_DII_raw_synthetic_Jan_Jun2026[Sector], J$1) -> 0 | K15: =SUMIFS(FII_DII_raw_synthetic_Jan_Jun2026[Net_Flow_Cr], FII_DII_raw_synthetic_Jan_Jun2026[Date], $A15, FII_DII_raw_synthetic_Jan_Jun2026[Entity_Type], "FII", FII_DII_raw_synthetic_Jan_Jun2026[Sector], K$1) -> 0 | L15: =SUMIFS(FII_DII_raw_synthetic_Jan_Jun2026[Net_Flow_Cr], FII_DII_raw_synthetic_Jan_Jun2026[Date], $A15, FII_DII_raw_synthetic_Jan_Jun2026[Entity_Type], "FII", FII_DII_raw_synthetic_Jan_Jun2026[Sector], L$1) -> -258.93 | M15: =SUMIFS(FII_DII_raw_synthetic_Jan_Jun2026[Net_Flow_Cr], FII_DII_raw_synthetic_Jan_Jun2026[Date], $A15, FII_DII_raw_synthetic_Jan_Jun2026[Entity_Type], "FII", FII_DII_raw_synthetic_Jan_Jun2026[Sector], M$1) -> -271.11 | N15: =SUMIFS(FII_DII_raw_synthetic_Jan_Jun2026[Net_Flow_Cr], FII_DII_raw_synthetic_Jan_Jun2026[Date], $A15, FII_DII_raw_synthetic_Jan_Jun2026[Entity_Type], "FII", FII_DII_raw_synthetic_Jan_Jun2026[Sector], N$1) -> 0 | ... P15: =SUMIFS(FII_DII_raw_synthetic_Jan_Jun2026[Net_Flow_Cr], FII_DII_raw_synthetic_Jan_Jun2026[Date], $A15, FII_DII_raw_synthetic_Jan_Jun2026[Entity_Type], "FII", FII_DII_raw_synthetic_Jan_Jun2026[Sector], P$1) -> 301.96 | Q15: {=SUMPRODUCT(ABS(G15:P15))} -> 832 | R15: {=LARGE(ABS(G15:P15),1)+LARGE(ABS(G15:P15),2)} -> 573.07 | S15: =IFERROR(R15/Q15,0) -> 0.68878606 | T15: =IFERROR(_xlfn.XLOOKUP(A15, 'Nifty 50 Historical Data'!A:A, 'Nifty 50 Historical Data'!G:G), "") -> -0.42 | W15: =IF(B15<=-$X$2,"Strong FII Selling",IF(B15>=$X$2,"Strong FII Buying",IF(OR(B15=0,C15=0),"Neutral",IF(SIGN(B15)<>SIGN(C15),"Divergent Flow","Aligned Flow")))) -> Divergent Flow | Y15: =WEEKNUM(A15,2) -> 4
A16: 46042 | B16: =SUMIFS(FII_DII_raw_synthetic_Jan_Jun2026[Net_Flow_Cr], FII_DII_raw_synthetic_Jan_Jun2026[Date], A16, FII_DII_raw_synthetic_Jan_Jun2026[Entity_Type], "FII") -> -362.42 | C16: =SUMIFS(FII_DII_raw_synthetic_Jan_Jun2026[Net_Flow_Cr], FII_DII_raw_synthetic_Jan_Jun2026[Date], A16, FII_DII_raw_synthetic_Jan_Jun2026[Entity_Type], "DII") -> -1119.55 | D16: =AVERAGE(B12:B16) -> -807.634 | E16: =AVERAGE(C12:C16) -> -700.672 | F16: =ABS(B16)-ABS(C16) -> -757.13 | G16: =SUMIFS(FII_DII_raw_synthetic_Jan_Jun2026[Net_Flow_Cr], FII_DII_raw_synthetic_Jan_Jun2026[Date], $A16, FII_DII_raw_synthetic_Jan_Jun2026[Entity_Type], "FII", FII_DII_raw_synthetic_Jan_Jun2026[Sector], G$1) -> 0 | H16: =SUMIFS(FII_DII_raw_synthetic_Jan_Jun2026[Net_Flow_Cr], FII_DII_raw_synthetic_Jan_Jun2026[Date], $A16, FII_DII_raw_synthetic_Jan_Jun2026[Entity_Type], "FII", FII_DII_raw_synthetic_Jan_Jun2026[Sector], H$1) -> 734.59 | I16: =SUMIFS(FII_DII_raw_synthetic_Jan_Jun2026[Net_Flow_Cr], FII_DII_raw_synthetic_Jan_Jun2026[Date], $A16, FII_DII_raw_synthetic_Jan_Jun2026[Entity_Type], "FII", FII_DII_raw_synthetic_Jan_Jun2026[Sector], I$1) -> 516.78 | J16: =SUMIFS(FII_DII_raw_synthetic_Jan_Jun2026[Net_Flow_Cr], FII_DII_raw_synthetic_Jan_Jun2026[Date], $A16, FII_DII_raw_synthetic_Jan_Jun2026[Entity_Type], "FII", FII_DII_raw_synthetic_Jan_Jun2026[Sector], J$1) -> 42.33 | K16: =SUMIFS(FII_DII_raw_synthetic_Jan_Jun2026[Net_Flow_Cr], FII_DII_raw_synthetic_Jan_Jun2026[Date], $A16, FII_DII_raw_synthetic_Jan_Jun2026[Entity_Type], "FII", FII_DII_raw_synthetic_Jan_Jun2026[Sector], K$1) -> 0 | L16: =SUMIFS(FII_DII_raw_synthetic_Jan_Jun2026[Net_Flow_Cr], FII_DII_raw_synthetic_Jan_Jun2026[Date], $A16, FII_DII_raw_synthetic_Jan_Jun2026[Entity_Type], "FII", FII_DII_raw_synthetic_Jan_Jun2026[Sector], L$1) -> 0 | M16: =SUMIFS(FII_DII_raw_synthetic_Jan_Jun2026[Net_Flow_Cr], FII_DII_raw_synthetic_Jan_Jun2026[Date], $A16, FII_DII_raw_synthetic_Jan_Jun2026[Entity_Type], "FII", FII_DII_raw_synthetic_Jan_Jun2026[Sector], M$1) -> 0 | N16: =SUMIFS(FII_DII_raw_synthetic_Jan_Jun2026[Net_Flow_Cr], FII_DII_raw_synthetic_Jan_Jun2026[Date], $A16, FII_DII_raw_synthetic_Jan_Jun2026[Entity_Type], "FII", FII_DII_raw_synthetic_Jan_Jun2026[Sector], N$1) -> -1656.12 | ... P16: =SUMIFS(FII_DII_raw_synthetic_Jan_Jun2026[Net_Flow_Cr], FII_DII_raw_synthetic_Jan_Jun2026[Date], $A16, FII_DII_raw_synthetic_Jan_Jun2026[Entity_Type], "FII", FII_DII_raw_synthetic_Jan_Jun2026[Sector], P$1) -> 0 | Q16: {=SUMPRODUCT(ABS(G16:P16))} -> 2949.82 | R16: {=LARGE(ABS(G16:P16),1)+LARGE(ABS(G16:P16),2)} -> 2390.71 | S16: =IFERROR(R16/Q16,0) -> 0.81045962 | T16: =IFERROR(_xlfn.XLOOKUP(A16, 'Nifty 50 Historical Data'!A:A, 'Nifty 50 Historical Data'!G:G), "") -> -1.38 | W16: =IF(B16<=-$X$2,"Strong FII Selling",IF(B16>=$X$2,"Strong FII Buying",IF(OR(B16=0,C16=0),"Neutral",IF(SIGN(B16)<>SIGN(C16),"Divergent Flow","Aligned Flow")))) -> Aligned Flow | Y16: =WEEKNUM(A16,2) -> 4
A17: 46043 | B17: =SUMIFS(FII_DII_raw_synthetic_Jan_Jun2026[Net_Flow_Cr], FII_DII_raw_synthetic_Jan_Jun2026[Date], A17, FII_DII_raw_synthetic_Jan_Jun2026[Entity_Type], "FII") -> -2813.09 | C17: =SUMIFS(FII_DII_raw_synthetic_Jan_Jun2026[Net_Flow_Cr], FII_DII_raw_synthetic_Jan_Jun2026[Date], A17, FII_DII_raw_synthetic_Jan_Jun2026[Entity_Type], "DII") -> 2840.95 | D17: =AVERAGE(B13:B17) -> -1457.366 | E17: =AVERAGE(C13:C17) -> 532.006 | F17: =ABS(B17)-ABS(C17) -> -27.86 | G17: =SUMIFS(FII_DII_raw_synthetic_Jan_Jun2026[Net_Flow_Cr], FII_DII_raw_synthetic_Jan_Jun2026[Date], $A17, FII_DII_raw_synthetic_Jan_Jun2026[Entity_Type], "FII", FII_DII_raw_synthetic_Jan_Jun2026[Sector], G$1) -> 0 | H17: =SUMIFS(FII_DII_raw_synthetic_Jan_Jun2026[Net_Flow_Cr], FII_DII_raw_synthetic_Jan_Jun2026[Date], $A17, FII_DII_raw_synthetic_Jan_Jun2026[Entity_Type], "FII", FII_DII_raw_synthetic_Jan_Jun2026[Sector], H$1) -> -126.75 | I17: =SUMIFS(FII_DII_raw_synthetic_Jan_Jun2026[Net_Flow_Cr], FII_DII_raw_synthetic_Jan_Jun2026[Date], $A17, FII_DII_raw_synthetic_Jan_Jun2026[Entity_Type], "FII", FII_DII_raw_synthetic_Jan_Jun2026[Sector], I$1) -> 0 | J17: =SUMIFS(FII_DII_raw_synthetic_Jan_Jun2026[Net_Flow_Cr], FII_DII_raw_synthetic_Jan_Jun2026[Date], $A17, FII_DII_raw_synthetic_Jan_Jun2026[Entity_Type], "FII", FII_DII_raw_synthetic_Jan_Jun2026[Sector], J$1) -> 0 | K17: =SUMIFS(FII_DII_raw_synthetic_Jan_Jun2026[Net_Flow_Cr], FII_DII_raw_synthetic_Jan_Jun2026[Date], $A17, FII_DII_raw_synthetic_Jan_Jun2026[Entity_Type], "FII", FII_DII_raw_synthetic_Jan_Jun2026[Sector], K$1) -> 0 | L17: =SUMIFS(FII_DII_raw_synthetic_Jan_Jun2026[Net_Flow_Cr], FII_DII_raw_synthetic_Jan_Jun2026[Date], $A17, FII_DII_raw_synthetic_Jan_Jun2026[Entity_Type], "FII", FII_DII_raw_synthetic_Jan_Jun2026[Sector], L$1) -> 0 | M17: =SUMIFS(FII_DII_raw_synthetic_Jan_Jun2026[Net_Flow_Cr], FII_DII_raw_synthetic_Jan_Jun2026[Date], $A17, FII_DII_raw_synthetic_Jan_Jun2026[Entity_Type], "FII", FII_DII_raw_synthetic_Jan_Jun2026[Sector], M$1) -> 0 | N17: =SUMIFS(FII_DII_raw_synthetic_Jan_Jun2026[Net_Flow_Cr], FII_DII_raw_synthetic_Jan_Jun2026[Date], $A17, FII_DII_raw_synthetic_Jan_Jun2026[Entity_Type], "FII", FII_DII_raw_synthetic_Jan_Jun2026[Sector], N$1) -> 0 | ... P17: =SUMIFS(FII_DII_raw_synthetic_Jan_Jun2026[Net_Flow_Cr], FII_DII_raw_synthetic_Jan_Jun2026[Date], $A17, FII_DII_raw_synthetic_Jan_Jun2026[Entity_Type], "FII", FII_DII_raw_synthetic_Jan_Jun2026[Sector], P$1) -> -1459.15 | Q17: {=SUMPRODUCT(ABS(G17:P17))} -> 2813.09 | R17: {=LARGE(ABS(G17:P17),1)+LARGE(ABS(G17:P17),2)} -> 2686.34 | S17: =IFERROR(R17/Q17,0) -> 0.95494279 | T17: =IFERROR(_xlfn.XLOOKUP(A17, 'Nifty 50 Historical Data'!A:A, 'Nifty 50 Historical Data'!G:G), "") -> -0.3 | W17: =IF(B17<=-$X$2,"Strong FII Selling",IF(B17>=$X$2,"Strong FII Buying",IF(OR(B17=0,C17=0),"Neutral",IF(SIGN(B17)<>SIGN(C17),"Divergent Flow","Aligned Flow")))) -> Strong FII Selling | Y17: =WEEKNUM(A17,2) -> 4
